Workbook

Sheet Hoja1
A1: Nº EXP. | B1: DÍA | C1: HORA | D1: TRABAJADOR/A | E1: EMPRESAS | F1: MOTIVOS | G1: EDAD | H1: Nº T. | I1: ANTG. EMPRE | J1: A | K1: Ñ | L1: O | N1: 2 | O1: 0 | P1: 2 | Q1: 2
A2: 1 | B2: 44573 | C2: 0.39583333 | D2: NOUR EDDINE MOHAMED MOHAMEDI | E2: HALIMA BUCHNACHI EL MESSAOUDI “PIZZERÍA LA ESPIGUERA” | F2: CANTIDAD Y RESOLUCIÓN DE CONTRATO A INSTANCIAS DEL TRABAJADOR
A3: 2 | B3: 44573 | C3: 0.39930556 | D3: OHL SERVICIOS INGESAN, S.A. | E3: ANA VICTORIA SCHILLER PIZANA | F3: CANTIDAD
A4: 3 | B4: 44573 | C4: 0.40277778 | D4: JACOBO RUIZ CORREA | E4: S.A. | F4: CANTIDAD
A5: 4 | B5: 44573 | C5: 0.40625 | D5: MIMOUN EL FEKRI | E5: MILADE, S.L. | F5: CANTIDAD
A6: 5 | B6: 44573 | C6: 0.40972222 | D6: ILHAM AHMED MOHAMED | E6: LIWE ESPAÑOLA, S.A. | F6: DESPIDO Y CANTIDAD
A7: 6 | B7: 44573 | C7: 0.41319444 | D7: ABDELLAH HAMMOUTI | E7: REFORMAS Y PROYECTOS COYSE MELILLA, S.L. | F7: CANTIDAD
A8: 7 | B8: 44573 | C8: 0.41666667 | D8: MALIKA HAMMU MOHAND | E8: TALHER, S.A. | F8: DERECHO Y CANTIDAD
A9: 8 | B9: 44573 | C9: 0.42013889 | D9: NURIA CARRETERO AVELINO | E9: MARÍA DEL CARMEN PALACIOS COBO | F9: DESPIDO Y CANTIDAD
A10: 9 | B10: 44573 | C10: 0.42361111 | D10: JAMAL ROUCHDI | E10: MOHAMED HADDOUCHI | F10: DESPIDO Y CANTIDAD
A11: 10 | B11: 44573 | C11: 0.42708333 | D11: TIJANI ZAHAF | E11: MAIR SADIA RUAS BELITY Y ALMIRU SL | F11: CANTIDAD
A12: 11 | B12: 44573 | C12: 0.43055556 | D12: ALI KASSEN AL LAL | E12: VALORIZA SERVICIOS MEDIOAMBIENTALES | F12: IMPUGNACIÓN SANCIÓN
A13: 12 | B13: 44573 | C13: 0.43402778 | D13: LLAMAL EL IDRISSI MOHAMED | E13: PROSEGUR SOLUCIONES INTEGRALES SEGURIDAD ESPAÑA SL | F13: DESPIDO NULO
... A70: 69 | B70: 44601 | C70: 0.39930556 | D70: NEZHA EL GUASSAA | E70: DRYCOLD GOOD, S.L. Y JOSÉ BENAIM ASERRAF | F70: DERECHO Y CANTIDAD
A71: 69 bis | B71: 44601 | C71: 0.39930556 | D71: NEZHA EL GUASSAA | E71: DRYCOLD GOOD, S.L. Y JOSÉ BENAIM ASERRAF | F71: DESPIDO NULO
A72: 70 | B72: 44601 | C72: 0.40277778 | D72: SAID TOURICH | E72: VALORIZA SERVICIOS MEDIOAMBIENTALES, S.A. | F72: DESPIDO
A73: 71 | B73: 44601 | C73: 0.40625 | D73: MHAMED EL OUARIACHI AMAKHTARI | E73: VALORIZA SERVICIOS MEDIOAMBIENTALES, S.A. | F73: DESPIDO
A74: 72 | B74: 44601 | C74: 0.40972222 | D74: ABDELHAKIM AL BANYAHYATI ZARIOH | E74: VALORIZA SERVICIOS MEDIOAMBIENTALES, S.A. | F74: DESPIDO
A75: 73 | B75: 44601 | C75: 0.41319444 | D75: KARIM MUSTAFA MIZZIAN | E75: SURESTE SEGURIDAD, S.L. | F75: DERECHO Y CANTIDAD
A76: 74 | B76: 44601 | C76: 0.41666667 | D76: FATIMA MATICHE LAHCEN, KARIMA BAGDAD MOHAMED, LUISA HAMETE BENZAR Y SALHA AHMED MOHAMED | E76: OHL SERVICIOS INGESAN, S.A. | F76: DERECHO Y CANTIDAD
A77: 75 | B77: 44601 | C77: 0.42013889 | D77: ABDELHUAHED AL LAL MOHAND | E77: VALORIZA SERVICIOS MEDIOAMBIENTALES | F77: DERECHO Y CANTIDAD
A78: 76 | B78: 44601 | C78: 0.42361111 | D78: ABDESLAM ABDESLAM SAIDI | E78: VALORIZA SERVICIOS MEDIOAMBIENTALES | F78: DESPIDO
A79: 77 | B79: 44601 | C79: 0.42708333 | D79: HAMZA SANHJI | E79: VALORIZA SERVICIOS MEDIOAMBIENTALES | F79: DESPIDO
A80: 78 | B80: 44601 | C80: 0.43055556 | D80: DUNIA HAMED BUMEDIEN | E80: VALORIZA SERVICIOS MEDIOAMBIENTALES | F80: DESPIDO
A81: 79 | B81: 44601 | C81: 0.43402778 | D81: FAUZI AMARUCH MOHAMEDI | E81: VALORIZA SERVICIOS MEDIOAMBIENTALES | F81: IMPUGNACIÓN MODIFICACIÓN SUSTANCIAL DE LAS CONDICIONES DE TRABAJO Y CANTIDAD
A82: 80 | B82: 44601 | C82: 0.4375 | D82: ENRIQUE RIVAS VILLATORO | E82: VALORIZA SERVICIOS MEDIOAMBIENTALES | F82: EXTINCIÓN DE LA RELACIÓN LABORAL (ART. 50)
A83: 81 | B83: 44608 | C83: 0.39583333 | D83: HAMID ABDELKADER MOHAMED | E83: INTBUILDER SEMA CONSTRUCCIÓN, S.L. | F83: DESPIDO Y CANTIDAD
... A103: 101 | B103: 44622 | C103: 0.39583333 | D103: MOHAMED SEBTI EL AIACHI | E103: ARQUISOCIAL, S.L. | F103: DERECHOS
A104: CC1/2022 | B104: 44610 | C104: 0.39583333 | D104: UGT MELILLA (DESISTIDO 17/02/2022) | E104: AMBULANCIAS TENORIO E HIJOS, S.L. | F104: DERECHO ABONO CANTIDADES ADEUDADAS TERCERA PAGA EXTRA Y PLUS DE RESIDENCIA
A105: 102 | B105: 44622 | C105: 0.39930556 | D105: MOHAMED SEBTI EL AIACHI | E105: ARQUISOCIAL, S.L. | F105: DERECHO Y CANTIDAD
A106: 103 | B106: 44622 | C106: 0.40277778 | D106: BORJA ARANA VEGA | E106: MANTENIMIENTOS TERRESTRES, S.L. | F106: CANTIDAD
A107: 104 | B107: 44622 | C107: 0.40625 | D107: PEDRO ARANA COBREROS | E107: MANTENIMIENOS TERRESTRES, S.L. | F107: CANTIDAD
A108: 105 | B108: 44622 | C108: 0.40972222 | D108: DRISS ARRAISS | E108: MARÍA JESÚS MILLÁN CEREÑO Y JESÚS BATALLA POO | F108: RESOLUCIÓN DE CONTRATO A INSTANCIA DEL TRABAJADOR
A109: 106 | B109: 44622 | C109: 0.41319444 | D109: FARID AMAR MOHAMED | E109: VALORIZA SERVICIOS MEDIOAMBIENTALES, S.A. | F109: DERECHO A JORNADA A TIEMPO COMPLETO Y VULNERACIÓN DE DERECHOS FUNDAMENTALES
A110: 107 | B110: 44622 | C110: 0.41666667 | D110: ABDELKARIM TAOUIL | E110: VALORIZA SERVICIOS MEDIOAMBIENTALES | F110: DERECHO Y CANTIDAD
A111: 108 | B111: 44622 | C111: 0.42013889 | D111: LOURDES GAONA GONZÁLEZ | E111: FUNDACIÓN DIAGRAMA INTERVENCIÓN PSICOSOCIAL | F111: DESPIDO
A112: 109 | B112: 44622 | C112: 0.42361111 | D112: JUAN ANTONIO ALCÁZAR HERNÁNDEZ | E112: TRAGSA SA EMPRESA TRANSFORMACIÓN AGRARIA | F112: CANTIDAD
A113: 110 | B113: 44622 | C113: 0.42708333 | D113: MOHAMED EL BASRI | E113: HOSSAIN AL LAL MAHMUD (CAFETERÍA LA TOJA) | F113: DESPIDO Y CANTIDAD
A114: 111 | B114: 44629 | C114: 0.39583333 | D114: HADRIEL MEHAMED GONZÁLEZ | E114: SURESTE SEGURIDAD, S.L. | F114: CANTIDAD
A115: 112 | B115: 44629 | C115: 0.39930556 | D115: AZEINE BENAAMAR | E115: TUFIK MOHAMED MOHAMEDI | F115: DESPIDO IMPROCEDENTE Y RECLAMACIÓN DE CANTIDAD
...

Sheet SERGIO
A1: SOLICITUD | B1: =Hoja1!A:A -> Nº EXP. | C1: =Hoja1!B:B -> DÍA | D1: =Hoja1!C:C -> HORA | E1: =Hoja1!D:D -> TRABAJADOR/A | F1: DNI | G1: REPRESENTANTE TRABAJADOR | H1: DNI REP. | I1: =Hoja1!E:E -> EMPRESAS | J1: CIF | K1: =Hoja1!F:F -> MOTIVOS
A2: 45636 | B2: 1 | C2: 45659 | D2: 0.39583333 | E2: MOHAMED OUHANNA | F2: Y8942625D | I2: JOSÉ ESCOBAR GÓMEZ | J2: 45314714J | K2: DESPIDO IMPROCEDENTE
A3: 45637 | B3: 2 | C3: 45659 | D3: 0.39930556 | E3: REDOUAN EL BOUDALI EL MOUDNI | F3: 44073884L | G3: FARID MOHAMED SAID | H3: 45308774Q | I3: CARAI MELILLA, S.L. Y FRANCISCO ANTONIO MENA GIL | J3: B52021052 Y | K3: RECONOCIMIENTO DE DERECHOS (ANTIGÜEDAD)
A4: 45631 | B4: 3 | C4: 45659 | D4: 0.40277778 | E4: INMACULADA GONZÁLEZ PEÑA | F4: 27382208H | G4: EVA GUILLÉN GARCÍA | H4: 05285148R | I4: ALVALOP SERVICIOS XXI, S.L.U. | J4: B36591063 | K4: RECLAMACIÓN POR SANCIÓN NULA O SUBSIDIARIAMENTE IMPROCEDENTE
A5: 45639 | B5: 4 | C5: 45659 | D5: 0.40625 | E5: ZACARIA EL BACHARI | F5: X4000771J | G5: FARID MOHAMED SAID | H5: 45308774Q | I5: BRAHIM HADDOUCHI EL BOUSNANI | J5: 44112399D | K5: DESPIDO Y RECLAMACIÓN DE CANTIDAD
A6: 45639 | B6: 5 | C6: 45666 | D6: 0.39583333 | E6: FUAD HAMED ALI | F6: 45298239S | G6: JOAQUÍN GARCÍA ANGOSTO | H6: 45314107J | I6: CARLOS ALMANSA LEAL Y VALORIZA SERVICIOS MEDIOAMBIENTALES SA | J6: 45315886K Y A28760692 | K6: RECONOCIMIENTO DE DERECHO Y RECLAMACIÓN SALARIAL
A7: 45639 | B7: 6 | C7: 45659 | D7: 0.40972222 | E7: CHAKIB NAJI NAJI | F7: 32996025H | G7: FARID MOHAMED SAID | H7: 45308774Q | I7: ADAMKAMAL SL | J7: B52037157 | K7: DESPIDO NULO CON VULNERACIÓN DE DERECHOS FUNDAMENTALES Y RECLAMACIÓN DE CANTIDADES
A8: 45639 | B8: 7 | C8: 45666 | D8: 0.39930556 | E8: NAFISA MOHAMED MOHAMED | F8: 45305994L | G8: FARID MOHAMED SAID | H8: 45308774Q | I8: TRANSFERLO SL, LOGISTIC EXPRESS ADUANA SLU, LEMALAGA SERVICIOS LOGISTICOS SL, DIRK MANUEL MARTENS JIMENEZ, MELILLA EXPRESS SL, LOGISTIC EXPRESS SL, AGENCIA MERIDA LOGISTICA SL, MACATRANS SL Y CABO EXPRESS SL | J8: B29903879, B44995355, B19886621, 78983770E, B29142320, B44803690, B93152171, B51035467 Y B29598307 | K8: DESPIDO IMPROCEDENTE Y RECLAMACIÓN DE CANTIDADES
A9: 45643 | B9: 8 | C9: 45659 | D9: 0.41319444 | E9: PAULA VICENTE MARCOS | F9: 7453718C | G9: FEDERICO BURLO DE ROJAS | H9: 33489971Q | I9: CLUB DEPORTIVO ELEMENTAL BALONMANO T-MARAVILLA | J9: G52040847 | K9: DESPIDO Y CANTIDAD
A10: 45644 | B10: 9 | C10: 45659 | D10: 0.41666667 | E10: SORAYA HADI DUDU | F10: 45301199P | G10: JOAQUÍN GARCÍA ANGOSTO | H10: 45314107J | I10: FUNDACIÓN DIAGRAMA INTERVENCIÓN PSICOSOCIAL | J10: G73038457 | K10: DESPIDO IMPROCEDENTE Y RECLAMACIÓN SALARIAL
A11: 45644 | B11: 10 | C11: 45666 | D11: 0.40277778 | E11: HASSAN KASSEN AL LAL | F11: 45282078T | G11: FARID AMED DRIS | H11: 45308923G | I11: VALORIZA SERVICIOS MEDIOAMBIENTALES, S.A. | J11: A28760692 | K11: IMPUGNACIÓN DE MODIFICACIÓN SUSTANCIAL DE LAS CONDICIONES DE TRABAJO CON VULNERACIÓN DE DERECHOS FUNDAMENTALES
A12: 45644 | B12: 11 | C12: 45659 | D12: 0.42361111 | E12: JOSÉ ANTONIO DOMÍNGUEZ MUÑOZ | F12: 44263941G | G12: ALBERTO J. REQUENA POU | H12: 45295631Y | I12: MELMATIC SL | J12: B29954955 | K12: DESPIDO IMPROCEDENTE Y RECLAMACIÓN DE CANTIDAD
A13: 45645 | B13: 12 | C13: 45666 | D13: 0.40625 | E13: FERNANDO JOSE OLIVARES AMAYA | F13: 45306935V | G13: JOAQUIN PEDRERO CEBALLOS | H13: 44264189E | I13: COOPERATIVA MAESTROS MELILLA (COMAMEL) | J13: F29953296 | K13: RECLAMACION DE DERECHO Y CANTIDAD
A14: 45645 | B14: 13 | C14: 45666 | D14: 0.40972222 | E14: TETIANA CHUCHAIEVA CHUCHAIEVA | F14: Y9292404G | G14: SALOMON SERFATY BITTAN | H14: 45288003Z | I14: EL CORTE INGLES S.A. | J14: A28017895 | K14: DESPIDO NULO Y RECONOCIMIENTO DE DERECHO
A15: 45646 | B15: 14 | C15: 45666 | D15: 0.41319444 | E15: JUAN JOSE VIÑAS DEL CASTILLO | F15: 45266987C | I15: PROYECTO MELILLA S.A. | J15: A29951753 | K15: RECONOCIMIENTO DE DERECHO Y RECLAMACION DE CANTIDAD
A16: 45649 | B16: 15 | C16: 45666 | D16: 0.41666667 | E16: MIMOUN EL FOUNTI KOHOUSS | F16: 60495102L | I16: MOHAMED ABDELKADER FATIHA | J16: 45288425E | K16: DESPIDO Y CANTIDAD
A17: 45649 | B17: 16 | C17: 45666 | D17: 0.42013889 | E17: TOURIYA EL MOURABIT | F17: Y8512904C | G17: DANIEL TEBAR CARMONA | H17: 45312120G | I17: LA AZOTEA MINAS DEL RIF, S.L. ALLAL BOULAATOUR MAACHOU SUFIAN BOULAATOUR MAACHOU | J17: B52041076 43995915C | K17: VULNERACION DE DERECHOS FUNDAMENTALES. RESOLUCION DEL CONTRATO.
A18: 45652 | B18: 17 | C18: 45666 | D18: 0.42361111 | E18: NABIL EL YOUSSFI | F18: Y1616849D | G18: FARID MOHAMED SAID | H18: 45308774Q | I18: CARAI MELILLA S.L. | J18: B52021052 | K18: DESPIDO IMPROCEDENTE Y RECLAMACIÓN DE CANTIDAD
A19: 45652 | B19: 18 | C19: 45666 | D19: 0.42708333 | E19: GUSTAVO ALEJANDRO BRAVO TORCOLETTI | F19: 43998344B | G19: FARID MOHAMED SAID | H19: 45308774Q | I19: ALMACENES DE PAPEL CASTAÑEDA | J19: B52013133 | K19: DESPIDO
A20: 45652 | B20: 19 | C20: 45666 | D20: 0.43055556 | E20: ABDESLAM YAHIAOUI | F20: X0936142L | G20: FARID MOHAMED SAID | H20: 45308774Q | I20: HEREDEROS DE EMILIO GALLEGO S.L. | J20: B52036969 | K20: RECLAMACION DE CANTIDAD
A21: 45652 | B21: 20 | C21: 45666 | D21: 0.43402778 | E21: JUAN JOSE JIMENEZ GARBIN | F21: 45317919F | I21: ALPHA SISTEMAS DE INFORMACION S.L. M.R. INFORMATICA S.L. CONECTICS ICT SERVICES SA-GETRONIC | J21: B82297904 B81230252 A48263693 | K21: DESPIDO IMPROCEDENTE Y RECLAMACIÓN DE CANTIDAD
A22: 45652 | B22: 21 | C22: 45666 | D22: 0.4375 | E22: JESUS PAREDES ROBLES | F22: 45311257S | I22: M.R. INFORMATICA S.L. CONECTICS ICT SERVICES SA-GETRONIC | J22: B81230252 A48263693 | K22: DESPIDO IMPROCEDENTE Y RECLAMACIÓN DE CANTIDAD
A23: 45654 | B23: 22 | C23: 45673 | D23: 0.4375 | E23: ÁNGEL ESTÉVANEZ CASAS | F23: 45321008Z | I23: M.R. INFORMÁTICA, S.L. Y GETRONIC, S.A. | J23: B81230252 Y A48263693 | K23: DESPIDO CON VULNERACIÓN DE DERECHOS FUNDAMENTALES EN MATERIA DE CESIÓN ILEGAL DE TRABAJADORES CON RECLAMACIÓN DE DIFERENCIAS SALARIALES
A24: 45653 | B24: 23 | C24: 45673 | D24: 0.44097222 | E24: 45659 | F24: 78946044Q | G24: JOAQUÍN GARCÍA ANGOSTO | H24: 45314107J | I24: ESGAMING SAU | J24: A86303773 | K24: RECLAMACIÓN SALARIAL
A25: 45653 | B25: 24 | C25: 45673 | D25: 0.44444444 | E25: MIRIAM CARMONA BETANCOR | F25: 42226973P | G25: JOAQUÍN GARCÍA ANGOSTO | H25: 45314107J | I25: RENVERSE SL | J25: B20781969 | K25: DESPIDO NULO Y RECLAMACIÓN SALARIAL
A26: 45653 | B26: 25 | C26: 45673 | D26: 0.44791667 | E26: FATIMA ZAHRA ELMIRABET | F26: Y8082528C | G26: JOAQUÍN GARCÍA ANGOSTO | H26: 45314107J | I26: PANADERÍA Y CONFITERÍA AROMA, S.L. | J26: B06806624 | K26: DESPIDO NULO
A27: 45656 | B27: 26 | C27: 45673 | D27: 0.52083333 | E27: JAVIER NÚÑEZ SUÁREZ | F27: 45314172D | G27: JOSÉ MARÍA IGNACIO SÁNCHEZ CHOLBI | H27: 45269826F | I27: MR INFORMÁTICA, S.L. | J27: B81230252 | K27: DESPIDO Y CANTIDAD
A28: 45659 | B28: 27 | C28: 45673 | D28: 0.45138889 | E28: GEMA MARÍA ZAPATA GIL | F28: 45303176F | I28: RB DENTAL SL | J28: B5203926 | K28: CLASIFICACIÓN PROFESIONAL Y DIFERENCIAS SALARIALES
A29: 45659 | B29: 28 | C29: 45673 | D29: 0.45486111 | E29: MUSTAFA BENAISA MOHAMED | F29: 45283737A | G29: FARID MOHAMED SAID | H29: 45308774Q | I29: SALZILLO SERVICIOS INTEGRALES, S.L. | J29: B73589814 | K29: CANTIDAD
A30: 45659 | B30: 29 | C30: 45673 | D30: 0.45833333 | E30: IGNACIO JOSÉ MÁS MOHAMED | F30: 45317586L | G30: GEMA FERRER RODRÍGUEZ | H30: 45300109E | I30: JYSK DBL IBERIA, S.L. | J30: B64935604 | K30: DESPIDO NULO O SUBSIDIARIAMENTE IMPROCEDENTE
A31: 45659 | B31: 30 | C31: 45673 | D31: 0.46180556 | E31: ASMA ROUDANE MOHAMED | F31: 45293008M | G31: FARID MOHAMED SAID | H31: 45308774Q | I31: CARAI MELILLA, S.L. | J31: B52021052 | K31: DESPIDO NULO CON VULNERACIÓN DE DERECHOS FUNDAMENTALES Y RECLAMACIÓN DE CANTIDADES
A32: 45659 | B32: 31 | C32: 45673 | D32: 0.52430556 | E32: MALIKA BACHIR HAMIDA | F32: 45283341K | G32: JOSÉ MARÍA IGNACIO SÁNCHEZ CHOLBI | H32: 45269826F | I32: CATERING LA HACIENDA, S.L. | J32: B97254403 | K32: DESPIDO Y CANTIDAD
A33: 45659 | B33: 32 | C33: 45673 | D33: 0.52777778 | E33: AHMED RUBIERA AHMED | F33: 45316280R | G33: JOSÉ MARÍA IGNACIO SÁNCHEZ CHOLBI | H33: 45269826F | I33: ACADEMIA SOCE, S.L. | J33: B51000131 | K33: DESPIDO Y CANTIDAD
A34: 45660 | B34: 33 | C34: 45673 | D34: 0.46527778 | E34: MARÍA DOLORES CABRERA BOLAÑOS | F34: 45301370H | G34: JOAQUÍN GARCÍA ANGOSTO | H34: 45314107J | I34: RENVERSE SL | J34: B20781969 | K34: DESPIDO NULO Y RECLAMACIÓN SALARIAL
A35: 45660 | B35: 34 | C35: 45673 | D35: 0.53125 | E35: HANAN BENKADDOU MUSTAFA | F35: 45307322J | G35: JOSÉ MARÍA IGNACIO SÁNCHEZ CHOLBI | H35: 45269826F | I35: JYSK DBL IBERIA SL | J35: B64935604 | K35: DESPIDO Y CANTIDAD
A36: 45660 | B36: 35 | C36: 45673 | D36: 0.53472222 | E36: SOURIA ACHAHBOUN ROTBI | F36: 44109873J | G36: JOSÉ MARÍA IGNACIO SÁNCHEZ CHOLBI | H36: 45269826F | I36: JYSK DBL IBERIA SL | J36: B64935604 | K36: DESPIDO Y CANTIDAD
A37: 45660 | B37: 36 | C37: 45673 | D37: 0.46875 | E37: SAMIRA RAHMANI MOHAMED | F37: 45315006S | G37: DAVID MARÍN SÁNCHEZ | H37: 45316553K | I37: ALVALOP SERVICIOS XXI, S.L.U. | J37: B36591063 | K37: RECONOCIMIENTO DE DERECHO Y RECLAMACIÓN DE CANTIDAD
A38: 45660 | B38: 37 | C38: 45680 | D38: 0.39583333 | E38: MOHATAR BEN CHAIB BOUTAHAR, RADUAN HAMIDA MIMUN, BORFA AMAR CHAIB, KARIM MOHAMED MOHAMED Y MOHAMED ABDESLAM MOHAMED | F38: 45281174Q, 45298688G, 45269301B, 45295362J Y 45287156H | G38: JOAQUÍN GARCÍA ANGOSTO | H38: 45314107J | I38: MIGUEL BAROJA DÍAZ, EULEN, S.A., HÉRCULES SERVICIOS GENERALES INTEGRALES Y REFORMAS MUSTAFA, S.L.U. | J38: 45297076W, A28517308, B51025591 Y B52019957 | K38: CESIÓN DE MANO DE OBRA Y RECLAMACIÓN SALARIAL
A39: 45660 | B39: 38 | C39: 45680 | D39: 0.375 | E39: ABDERRAZAK BELLAHSEN | F39: X7143307J | G39: JOSÉ MARÍA IGNACIO SÁNCHEZ CHOLBI | H39: 45269826F | I39: JAVIER RAMOS BENGUIGUI | J39: 45286760J | K39: CANTIDAD
A40: 45660 | B40: 39 | C40: 45680 | D40: 0.37847222 | E40: SAID TOUHOU | F40: X3567237Y | G40: JOSÉ MARÍA IGNACIO SÁNCHEZ CHOLBI | H40: 45269826F | I40: JAVIER RAMOS BENGUIGUI | J40: 45286760J | K40: CANTIDAD
...

Sheet LISTADO CITACIONES
B1: LISTADO CITACIONES 29 DE JULIO 2022
A2: =Hoja1!B1 -> DÍA | B2: =Hoja1!C1 -> HORA | C2: TRABAJADOR | D2: REPRESENTANTE TRAB. | E2: EMPRESA
A3: =Hoja1!B2 -> 44573 | B3: =Hoja1!C2 -> 0.39583333 | C3: =Hoja1!D2 -> NOUR EDDINE MOHAMED MOHAMEDI | D3: =SERGIO!G2 -> 0 | E3: =Hoja1!E2 -> HALIMA BUCHNACHI EL MESSAOUDI “PIZZERÍA LA ESPIGUERA”
A4: =Hoja1!B3 -> 44573 | B4: =Hoja1!C3 -> 0.39930556 | C4: =Hoja1!D3 -> OHL SERVICIOS INGESAN, S.A. | D4: =SERGIO!G3 -> FARID MOHAMED SAID | E4: =Hoja1!E3 -> ANA VICTORIA SCHILLER PIZANA
A5: =Hoja1!B4 -> 44573 | B5: =Hoja1!C4 -> 0.40277778 | C5: =Hoja1!D4 -> JACOBO RUIZ CORREA | D5: =SERGIO!G4 -> EVA GUILLÉN GARCÍA | E5: =Hoja1!E4 -> S.A.
A6: =Hoja1!B5 -> 44573 | B6: =Hoja1!C5 -> 0.40625 | C6: =Hoja1!D5 -> MIMOUN EL FEKRI | D6: =SERGIO!G5 -> FARID MOHAMED SAID | E6: =Hoja1!E5 -> MILADE, S.L.
A7: =Hoja1!B6 -> 44573 | B7: =Hoja1!C6 -> 0.40972222 | C7: =Hoja1!D6 -> ILHAM AHMED MOHAMED | D7: =SERGIO!G6 -> JOAQUÍN GARCÍA ANGOSTO | E7: =Hoja1!E6 -> LIWE ESPAÑOLA, S.A.
A8: =Hoja1!B7 -> 44573 | B8: =Hoja1!C7 -> 0.41319444 | C8: =Hoja1!D7 -> ABDELLAH HAMMOUTI | D8: =SERGIO!G7 -> FARID MOHAMED SAID | E8: =Hoja1!E7 -> REFORMAS Y PROYECTOS COYSE MELILLA, S.L.
A9: =Hoja1!B8 -> 44573 | B9: =Hoja1!C8 -> 0.41666667 | C9: =Hoja1!D8 -> MALIKA HAMMU MOHAND | D9: =SERGIO!G8 -> FARID MOHAMED SAID | E9: =Hoja1!E8 -> TALHER, S.A.
A10: =Hoja1!B9 -> 44573 | B10: =Hoja1!C9 -> 0.42013889 | C10: =Hoja1!D9 -> NURIA CARRETERO AVELINO | D10: =SERGIO!G9 -> FEDERICO BURLO DE ROJAS | E10: =Hoja1!E9 -> MARÍA DEL CARMEN PALACIOS COBO
A11: =Hoja1!B10 -> 44573 | B11: =Hoja1!C10 -> 0.42361111 | C11: =Hoja1!D10 -> JAMAL ROUCHDI | D11: =SERGIO!G10 -> JOAQUÍN GARCÍA ANGOSTO | E11: =Hoja1!E10 -> MOHAMED HADDOUCHI
A12: =Hoja1!B11 -> 44573 | B12: =Hoja1!C11 -> 0.42708333 | C12: =Hoja1!D11 -> TIJANI ZAHAF | D12: =SERGIO!G11 -> FARID AMED DRIS | E12: =Hoja1!E11 -> MAIR SADIA RUAS BELITY Y ALMIRU SL
A13: =Hoja1!B12 -> 44573 | B13: =Hoja1!C12 -> 0.43055556 | C13: =Hoja1!D12 -> ALI KASSEN AL LAL | D13: =SERGIO!G12 -> ALBERTO J. REQUENA POU | E13: =Hoja1!E12 -> VALORIZA SERVICIOS MEDIOAMBIENTALES
A14: =Hoja1!B13 -> 44573 | B14: =Hoja1!C13 -> 0.43402778 | C14: =Hoja1!D13 -> LLAMAL EL IDRISSI MOHAMED | D14: =SERGIO!G13 -> JOAQUIN PEDRERO CEBALLOS | E14: =Hoja1!E13 -> PROSEGUR SOLUCIONES INTEGRALES SEGURIDAD ESPAÑA SL
... A69: =Hoja1!B68 -> 44594 | B69: =Hoja1!C68 -> 0.45486111 | C69: =Hoja1!D68 -> JAKIN AHMED MIMUN | D69: =SERGIO!G68 -> 0 | E69: =Hoja1!E68 -> VALORIZA SERVICIOS MEDIOAMBIENTALES
A70: =Hoja1!B69 -> 44594 | B70: =Hoja1!C69 -> 0.45833333 | C70: =Hoja1!D69 -> SAMIR AMJAHAD TAHIRI | D70: =SERGIO!I69 -> ASOCIACION DE EMPRESARIOS DE INSTALADORES Y MANTENDEDORES DE MELILLA SINDICATO CCOO FEDERACIÓN DE INDUSTRIA, CONSTRUCCIÓN Y AGRO-UGT | E70: =Hoja1!E69 -> VALORIZA SERVICIOS MEDIOAMBIENTALES
A71: =Hoja1!B70 -> 44601 | B71: =Hoja1!C70 -> 0.39930556 | C71: =Hoja1!D70 -> NEZHA EL GUASSAA | D71: =SERGIO!G70 -> JOSÉ MARÍA IGNACIO SÁNCHEZ CHOLBI | E71: =Hoja1!E70 -> DRYCOLD GOOD, S.L. Y JOSÉ BENAIM ASERRAF
A72: =Hoja1!B71 -> 44601 | B72: =Hoja1!C71 -> 0.39930556 | C72: =Hoja1!D71 -> NEZHA EL GUASSAA | D72: =SERGIO!G71 -> MARÍA DOLORES LÓPEZ GUARDIA | E72: =Hoja1!E71 -> DRYCOLD GOOD, S.L. Y JOSÉ BENAIM ASERRAF
A73: =Hoja1!B72 -> 44601 | B73: =Hoja1!C72 -> 0.40277778 | C73: =Hoja1!D72 -> SAID TOURICH | D73: =SERGIO!G72 -> FARID MOHAMED SAID | E73: =Hoja1!E72 -> VALORIZA SERVICIOS MEDIOAMBIENTALES, S.A.
A74: =Hoja1!B73 -> 44601 | B74: =Hoja1!C73 -> 0.40625 | C74: =Hoja1!D73 -> MHAMED EL OUARIACHI AMAKHTARI | D74: =SERGIO!G77 -> FARID MOHAMED SAID | E74: =Hoja1!E73 -> VALORIZA SERVICIOS MEDIOAMBIENTALES, S.A.
A75: =Hoja1!B74 -> 44601 | B75: =Hoja1!C74 -> 0.40972222 | C75: =Hoja1!D74 -> ABDELHAKIM AL BANYAHYATI ZARIOH | D75: =SERGIO!G74 -> JOAQUÍN PEDRERO CEBALLOS | E75: =Hoja1!E74 -> VALORIZA SERVICIOS MEDIOAMBIENTALES, S.A.
A76: =Hoja1!B75 -> 44601 | B76: =Hoja1!C75 -> 0.41319444 | C76: =Hoja1!D75 -> KARIM MUSTAFA MIZZIAN | D76: =SERGIO!G75 -> FARID MOHAMED SAID | E76: =Hoja1!E75 -> SURESTE SEGURIDAD, S.L.
A77: =Hoja1!B76 -> 44601 | B77: =Hoja1!C76 -> 0.41666667 | C77: =Hoja1!D76 -> FATIMA MATICHE LAHCEN, KARIMA BAGDAD MOHAMED, LUISA HAMETE BENZAR Y SALHA AHMED MOHAMED | D77: =SERGIO!G76 -> FARID MOHAMED SAID | E77: =Hoja1!E76 -> OHL SERVICIOS INGESAN, S.A.
A78: =Hoja1!B77 -> 44601 | B78: =Hoja1!C77 -> 0.42013889 | C78: =Hoja1!D77 -> ABDELHUAHED AL LAL MOHAND | D78: =SERGIO!G77 -> FARID MOHAMED SAID | E78: =Hoja1!E77 -> VALORIZA SERVICIOS MEDIOAMBIENTALES
A79: =Hoja1!B78 -> 44601 | B79: =Hoja1!C78 -> 0.42361111 | C79: =Hoja1!D78 -> ABDESLAM ABDESLAM SAIDI | D79: =SERGIO!G78 -> FARID MOHAMED SAID | E79: =Hoja1!E78 -> VALORIZA SERVICIOS MEDIOAMBIENTALES
A80: =Hoja1!B79 -> 44601 | B80: =Hoja1!C79 -> 0.42708333 | C80: =Hoja1!D79 -> HAMZA SANHJI | D80: =SERGIO!G79 -> 0 | E80: =Hoja1!E79 -> VALORIZA SERVICIOS MEDIOAMBIENTALES
A81: =Hoja1!B80 -> 44601 | B81: =Hoja1!C80 -> 0.43055556 | C81: =Hoja1!D80 -> DUNIA HAMED BUMEDIEN | D81: =SERGIO!G80 -> FARID MOHAMED SAID | E81: =Hoja1!E80 -> VALORIZA SERVICIOS MEDIOAMBIENTALES
A82: =Hoja1!B81 -> 44601 | B82: =Hoja1!C81 -> 0.43402778 | C82: =Hoja1!D81 -> FAUZI AMARUCH MOHAMEDI | D82: =SERGIO!G81 -> JOAQUÍN GARCÍA ANGOSTO | E82: =Hoja1!E81 -> VALORIZA SERVICIOS MEDIOAMBIENTALES
A83: =Hoja1!B82 -> 44601 | B83: =Hoja1!C82 -> 0.4375 | C83: =Hoja1!D82 -> ENRIQUE RIVAS VILLATORO | D83: =SERGIO!G82 -> 0 | E83: =Hoja1!E82 -> VALORIZA SERVICIOS MEDIOAMBIENTALES
A84: =Hoja1!B83 -> 44608 | B84: =Hoja1!C83 -> 0.39583333 | C84: =Hoja1!D83 -> HAMID ABDELKADER MOHAMED | D84: =SERGIO!G83 -> ALBERTO JOSÉ REQUENA POU | E84: =Hoja1!E83 -> INTBUILDER SEMA CONSTRUCCIÓN, S.L.
A85: =Hoja1!B84 -> 44608 | B85: =Hoja1!C84 -> 0.39930556 | C85: =Hoja1!D84 -> JOSÉ DAVID FERNÁNDEZ CORNEJO | D85: =SERGIO!I84 -> JOAQUÍN AZNAR GUERRA | E85: =Hoja1!E84 -> INTBUILDER SEMA CONSTRUCCIÓN, S.L.
A86: =Hoja1!B85 -> 44608 | B86: =Hoja1!C85 -> 0.40277778 | C86: =Hoja1!D85 -> EL MOSTAPHA BAHRI LAMKADDAM | D86: =SERGIO!G85 -> MARTA ALONSO SALGADO | E86: =Hoja1!E85 -> INTBUILDER SEMA CONSTRUCCIÓN, S.L.
A87: =Hoja1!B86 -> 44608 | B87: =Hoja1!C86 -> 0.40625 | C87: =Hoja1!D86 -> ALI BOUALALA YAKHLEF | D87: =SERGIO!G86 -> MARTA ALONSO SALGADO | E87: =Hoja1!E86 -> DORANJO, S.L.U.
A88: =Hoja1!B87 -> 44608 | B88: =Hoja1!C87 -> 0.40972222 | C88: =Hoja1!D87 -> RACHIB EL AMMOURI | D88: =SERGIO!G87 -> JOSÉ LUIS LEÓN MARCOS | E88: =Hoja1!E87 -> GERCAR CONSTRUCCIONES Y REFORMAS
A89: =Hoja1!B88 -> 44608 | B89: =Hoja1!C88 -> 0.41319444 | C89: =Hoja1!D88 -> SAMIR AZDI AHMED | D89: =SERGIO!G88 -> JOSÉ LUIS LEÓN MARCOS | E89: =Hoja1!E88 -> MARIANO REMARTÍNEZ BUERA
A90: =Hoja1!B89 -> 44615 | B90: =Hoja1!C89 -> 0.39583333 | C90: =Hoja1!D89 -> YAMILA MOHATAR MOH | D90: =SERGIO!G89 -> JOSÉ LUIS LEÓN MARCOS | E90: =Hoja1!E89 -> COMERCIAL ESPAÑOLA DE RECAMBIOS Y AUTOMÓVILES, S.A. Y CERAS, S.L.
A91: =Hoja1!B90 -> 44615 | B91: =Hoja1!C90 -> 0.39930556 | C91: =Hoja1!D90 -> USAMA EL KAYCHOUHI BENSIALI | D91: =SERGIO!G90 -> JOSÉ LUIS LEÓN MARCOS | E91: =Hoja1!E90 -> JM FONTANEROS MELILLA, S.L.
A92: =Hoja1!B91 -> 44615 | B92: =Hoja1!C91 -> 0.40277778 | C92: =Hoja1!D91 -> MHAMED ZARIOUHI | D92: =SERGIO!G91 -> JOSÉ LUIS LEÓN MARCOS | E92: =Hoja1!E91 -> CANALIZACIONES Y CENTROS MELILLA, S.L. (CAYCEMEL)
A93: =Hoja1!B92 -> 44615 | B93: =Hoja1!C92 -> 0.40625 | C93: =Hoja1!D92 -> SORAIDA MOHAMED FATMI | D93: =SERGIO!G92 -> JOSÉ LUIS LEÓN MARCOS | E93: =Hoja1!E92 -> RUSADIR MEDIA, S.L.
A94: =Hoja1!B93 -> 44615 | B94: =Hoja1!C93 -> 0.40972222 | C94: =Hoja1!D93 -> JOSÉ MARÍA MORALES MORENO | D94: =SERGIO!G93 -> JOSÉ LUIS LEÓN MARCOS | E94: =Hoja1!E93 -> SURESTE SEGURIDAD, S.L.
...

Sheet Hoja4
